<?xml version="1.0" ?>
<robot name="my_bot" xmlns:xacro="http://www.ros.org/wiki/xacro">

  <link name="base_link">
    <origin xyz="0.0 0.0 0.0" rpy="0.0 0.0 0.0"/>
  </link>
  
  <joint name="base_joint" type="fixed">
    <parent link="base_link"/>
    <child link="chassis"/>
    <origin xyz="0 0 0" rpy="0 0 0"/>
  </joint>

  <link name="chassis">
    <visual>
      <origin xyz="0 0 0" rpy="0 0 0"/>
      <geometry>
        <mesh filename="file://$(find basic_robot)/meshes/chassis.stl" scale="0.1 0.1 0.1"/>
      </geometry>
    </visual>
    <collision>
      <origin xyz="0 0 0" rpy="0 0 0"/>
      <geometry>
        <mesh filename="file://$(find basic_robot)/meshes/chassis.stl" scale="0.1 0.1 0.1"/>
      </geometry>
    </collision>
    <inertial>
      <origin xyz="0.0 0.0 0.0" rpy="0 0 0"/>
      <mass value="10"/>
      <inertia  ixx="0.42" ixy="0" ixz="0" iyy="1.042" iyz="0" izz="1.042" />
    </inertial>
  </link>

  <link name="left_wheel_1">
    
    <inertial>
      <origin xyz="0 0 0" rpy="0 0 0"/>
      <mass value="5"/>
      <inertia  ixx="0.5327296181012307" ixy="0" ixz="0" iyy="0.3035629514345639" iyz="0" izz="0.30416666666666675" />
    </inertial>
    
    <visual>
      <origin xyz="0.5 -0.0 -0.25" rpy="0 0 0"/>
      <geometry>
        <mesh filename="file://$(find basic_robot)/meshes/left_wheel_1.stl" scale="0.1 0.1 0.1"/>
      </geometry>
    </visual>
    <collision>
      <origin xyz="0.5 -0.0 -0.25" rpy="0 0 0"/>
      <geometry>
        <mesh filename="file://$(find basic_robot)/meshes/left_wheel_1.stl" scale="0.1 0.1 0.1"/>
      </geometry>
    </collision>
  </link>

  <link name="right_wheel_1">
    
    <inertial>
      <origin xyz="0 0 0" rpy="0 0 0"/>
      <mass value="5"/>
      <inertia  ixx="0.5327295545949559" ixy="0" ixz="0" iyy="0.3035628879282892" iyz="0" izz="0.30416666666666675" />
    </inertial>
    
    <visual>
      <origin xyz="-0.5 -0.0 -0.25" rpy="0 0 0"/>
      <geometry>
        <mesh filename="file://$(find basic_robot)/meshes/right_wheel_1.stl" scale="0.1 0.1 0.1"/>
      </geometry>
    </visual>
    <collision>
      <origin xyz="-0.5 -0.0 -0.25" rpy="0 0 0"/>
      <geometry>
        <mesh filename="file://$(find basic_robot)/meshes/right_wheel_1.stl" scale="0.1 0.1 0.1"/>
      </geometry>
    </collision>
  </link>

  <joint name="Revolute1" type="continuous">
    <origin xyz="-0.5 0.0 0.25" rpy="0 0 0"/>
    <parent link="chassis"/>
    <child link="left_wheel_1"/>
    <axis xyz="-1.0 0.0 0.0"/>
  </joint>

  <joint name="Revolute2" type="continuous">
    <origin xyz="0.5 0.0 0.25" rpy="0 0 0"/>
    <parent link="chassis"/>
    <child link="right_wheel_1"/>
    <axis xyz="1.0 0.0 0.0"/>
  </joint>
  
  <gazebo reference="left_wheel_1">
    <mu1 value="0.001"/>
    <mu2 value="0.001"/>
  </gazebo>

  <gazebo reference="right_wheel_1">
    <mu1 value="0.001"/>
    <mu2 value="0.001"/>
  </gazebo>
</robot>
